Workbook
Name ViewYear: 'Skill Matrix'!$B$3
Name EmployeeList: 'Employees'!$B$6:INDEX('Employees'!$B$6:$B$21,COUNTA('Employees'!$B$6:$B$21))
Name SkillNameList: 'Skills'!$B$6:INDEX('Skills'!$B$6:$B$21,COUNTA('Skills'!$B$6:$B$21))
Name YearList: 'Years'!$B$8:INDEX('Years'!$B$8:$B$23,COUNTA('Years'!$B$8:$B$23))
Name ViewModeList: 'Lists'!$C$6:$C$8
Name DepartmentList: 'Lists'!$A$6:INDEX('Lists'!$A$6:$A$21,COUNTA('Lists'!$A$6:$A$21))
Name DeptFilterList: 'Lists'!$E$6:INDEX('Lists'!$E$6:$E$22,COUNTA('Lists'!$E$6:$E$22))
Name TargetRating: 'Settings'!$B$6
Name CalendarYear: 'Settings'!$B$9
Name DataEmployee: 'Data'!$A$2:$A$4097
Name DataDept: 'Data'!$B$2:$B$4097
Name DataSkill: 'Data'!$C$2:$C$4097
Name DataYear: 'Data'!$E$2:$E$4097
Name DataRating: 'Data'!$F$2:$F$4097
Name LatestYear: 'Calc'!$B$1
Name PreviousYear: 'Calc'!$B$2
Name ViewMode: 'Dashboard'!$B$5
Name DashFromYear: 'Dashboard'!$D$5
Name DashToYear: 'Dashboard'!$F$5
Name DeptFilter: 'Dashboard'!$B$6
Name SkillSetFilter: 'Dashboard'!$D$6
Name EmpFilter: 'Dashboard'!$F$6

Sheet How to Use
A1: Company logo | C1: How to Use | D1: Skill Matrix | E1: Dashboard | F1: Employees | G1: Skills | H1: Years | I1: Lists | J1: Settings
C2: How to use this skill matrix
A3: Skill Matrix is this year's grid. On Dashboard, start with Look at: Team, Skillsets, or Individual. Insert a company logo once in the top-left box (Insert > Pictures > Place in Cell). It appears on every tab. Ratings is hidden until you Unhide it.
A5: 1. This year's crew grid | G5: 2. Dashboard — pick what to look at
A6: Open Skill Matrix. Each row is one person. Each column is one skillset, coloured 1 (red) to 5 (green). Overall is that person's average. The highest overall is highlighted in gold. Only this calendar year is shown (or pick another year at the top). To type 1-5: right-click a sheet tab, Unhide, choose Ratings. Then Hide it again when you are done. | G6: Look at: Team, Skillsets, or Individual. Then pick From year and To year. Team — year-on-year overall ratings (optionally one department). Skillsets — pick a skill in the Skillset dropdown. Everyone is ranked on that job. Top row is the best candidate. Individual — pick a person in the Employee dropdown. That person vs themselves on each skillset.
A16: 3. Add people and skillsets | G16: 4. Ratings (hidden) and new years
A17: Employees — next yellow row. Type the name, pick Department (Vision, Sound, Lighting, Staging), fill Hire date. Skillsets — next yellow row on Skills. Every person gets a rating row, and Dashboard can rank who is strongest on it. Lists — departments only. Keep using this file as you add people and scores. A newly generated workbook would not include them unless you copy the data across (see README). | G17: Ratings holds every year. It is hidden so the tabs stay simple. Recall it: right-click any sheet tab > Unhide > Ratings. Hide it the same way when finished. Years 2023-2034 are already columns. To add 2035 or later, type it on Years in the next yellow row.
A26: Rating scale
A27: 1 Beginner | C27: 2 Basic | E27: 3 Competent | G27: 4 Proficient | I27: 5 Expert
A28: Little or no hands-on experience. Needs close guidance. | C28: Can complete simple tasks with help or a checklist. | E28: Works independently on standard tasks. Meets the target. | G28: Handles complex work and can coach others. | I28: Go-to specialist. Sets the standard for the team.
A31: Microsoft 365 / Excel 2021+ is recommended (MAXIFS, SUMIFS, LOOKUP). Ratings is hidden (Unhide from a sheet tab). Data/Calc stay hidden — do not edit those.

Sheet Skill Matrix
A1: ='How to Use'!A1 | C1: How to Use | D1: Skill Matrix | E1: Dashboard | F1: Employees | G1: Skills | H1: Years | I1: Lists | J1: Settings
C2: Crew skill matrix | G2: This year's scores only. Compare years on the Dashboard.
A3: Year | B3: =CalendarYear | C3: Each skill is coloured 1 (red) to 5 (green). Overall is the average for this year. The highest overall is highlighted. Compare years on the Dashboard. To type 1-5: right-click a sheet tab, Unhide, choose Ratings.
A4: Employee | B4: Department | C4: Overall | D4: =IF('Skills'!B6="","",'Skills'!C6) | E4: =IF('Skills'!B7="","",'Skills'!C7) | F4: =IF('Skills'!B8="","",'Skills'!C8) | G4: =IF('Skills'!B9="","",'Skills'!C9) | H4: =IF('Skills'!B10="","",'Skills'!C10) | I4: =IF('Skills'!B11="","",'Skills'!C11) | J4: =IF('Skills'!B12="","",'Skills'!C12) | K4: =IF('Skills'!B13="","",'Skills'!C13) | L4: =IF('Skills'!B14="","",'Skills'!C14) | M4: =IF('Skills'!B15="","",'Skills'!C15) | N4: =IF('Skills'!B16="","",'Skills'!C16) | O4: =IF('Skills'!B17="","",'Skills'!C17) | P4: =IF('Skills'!B18="","",'Skills'!C18) | Q4: =IF('Skills'!B19="","",'Skills'!C19) | R4: =IF('Skills'!B20="","",'Skills'!C20) | S4: =IF('Skills'!B21="","",'Skills'!C21)
D5: =IF('Skills'!B6="","",'Skills'!B6) | E5: =IF('Skills'!B7="","",'Skills'!B7) | F5: =IF('Skills'!B8="","",'Skills'!B8) | G5: =IF('Skills'!B9="","",'Skills'!B9) | H5: =IF('Skills'!B10="","",'Skills'!B10) | I5: =IF('Skills'!B11="","",'Skills'!B11) | J5: =IF('Skills'!B12="","",'Skills'!B12) | K5: =IF('Skills'!B13="","",'Skills'!B13) | L5: =IF('Skills'!B14="","",'Skills'!B14) | M5: =IF('Skills'!B15="","",'Skills'!B15) | N5: =IF('Skills'!B16="","",'Skills'!B16) | O5: =IF('Skills'!B17="","",'Skills'!B17) | P5: =IF('Skills'!B18="","",'Skills'!B18) | Q5: =IF('Skills'!B19="","",'Skills'!B19) | R5: =IF('Skills'!B20="","",'Skills'!B20) | S5: =IF('Skills'!B21="","",'Skills'!B21)
A6: =IF('Employees'!B6="","",'Employees'!B6) | B6: =IF(A6="","",'Employees'!C6) | C6: =IF($A6="","",IFERROR(ROUND(AVERAGE(D6:S6),2),"")) | D6: =IF(OR($A6="",D$5="",ViewYear=""),"",IF(SUMIFS(DataRating,DataEmployee,$A6,DataSkill,D$5,DataYear,ViewYear)=0,"",SUMIFS(DataRating,DataEmployee,$A6,DataSkill,D$5,DataYear,ViewYear))) | E6: =IF(OR($A6="",E$5="",ViewYear=""),"",IF(SUMIFS(DataRating,DataEmployee,$A6,DataSkill,E$5,DataYear,ViewYear)=0,"",SUMIFS(DataRating,DataEmployee,$A6,DataSkill,E$5,DataYear,ViewYear))) | F6: =IF(OR($A6="",F$5="",ViewYear=""),"",IF(SUMIFS(DataRating,DataEmployee,$A6,DataSkill,F$5,DataYear,ViewYear)=0,"",SUMIFS(DataRating,DataEmployee,$A6,DataSkill,F$5,DataYear,ViewYear))) | G6: =IF(OR($A6="",G$5="",ViewYear=""),"",IF(SUMIFS(DataRating,DataEmployee,$A6,DataSkill,G$5,DataYear,ViewYear)=0,"",SUMIFS(DataRating,DataEmployee,$A6,DataSkill,G$5,DataYear,ViewYear))) | H6: =IF(OR($A6="",H$5="",ViewYear=""),"",IF(SUMIFS(DataRating,DataEmployee,$A6,DataSkill,H$5,DataYear,ViewYear)=0,"",SUMIFS(DataRating,DataEmployee,$A6,DataSkill,H$5,DataYear,ViewYear))) | I6: =IF(OR($A6="",I$5="",ViewYear=""),"",IF(SUMIFS(DataRating,DataEmployee,$A6,DataSkill,I$5,DataYear,ViewYear)=0,"",SUMIFS(DataRating,DataEmployee,$A6,DataSkill,I$5,DataYear,ViewYear))) | J6: =IF(OR($A6="",J$5="",ViewYear=""),"",IF(SUMIFS(DataRating,DataEmployee,$A6,DataSkill,J$5,DataYear,ViewYear)=0,"",SUMIFS(DataRating,DataEmployee,$A6,DataSkill,J$5,DataYear,ViewYear))) | K6: =IF(OR($A6="",K$5="",ViewYear=""),"",IF(SUMIFS(DataRating,DataEmployee,$A6,DataSkill,K$5,DataYear,ViewYear)=0,"",SUMIFS(DataRating,DataEmployee,$A6,DataSkill,K$5,DataYear,ViewYear))) | ... S6: =IF(OR($A6="",S$5="",ViewYear=""),"",IF(SUMIFS(DataRating,DataEmployee,$A6,DataSkill,S$5,DataYear,ViewYear)=0,"",SUMIFS(DataRating,DataEmployee,$A6,DataSkill,S$5,DataYear,ViewYear)))
A7: =IF('Employees'!B7="","",'Employees'!B7) | B7: =IF(A7="","",'Employees'!C7) | C7: =IF($A7="","",IFERROR(ROUND(AVERAGE(D7:S7),2),"")) | D7: =IF(OR($A7="",D$5="",ViewYear=""),"",IF(SUMIFS(DataRating,DataEmployee,$A7,DataSkill,D$5,DataYear,ViewYear)=0,"",SUMIFS(DataRating,DataEmployee,$A7,DataSkill,D$5,DataYear,ViewYear))) | E7: =IF(OR($A7="",E$5="",ViewYear=""),"",IF(SUMIFS(DataRating,DataEmployee,$A7,DataSkill,E$5,DataYear,ViewYear)=0,"",SUMIFS(DataRating,DataEmployee,$A7,DataSkill,E$5,DataYear,ViewYear))) | F7: =IF(OR($A7="",F$5="",ViewYear=""),"",IF(SUMIFS(DataRating,DataEmployee,$A7,DataSkill,F$5,DataYear,ViewYear)=0,"",SUMIFS(DataRating,DataEmployee,$A7,DataSkill,F$5,DataYear,ViewYear))) | G7: =IF(OR($A7="",G$5="",ViewYear=""),"",IF(SUMIFS(DataRating,DataEmployee,$A7,DataSkill,G$5,DataYear,ViewYear)=0,"",SUMIFS(DataRating,DataEmployee,$A7,DataSkill,G$5,DataYear,ViewYear))) | H7: =IF(OR($A7="",H$5="",ViewYear=""),"",IF(SUMIFS(DataRating,DataEmployee,$A7,DataSkill,H$5,DataYear,ViewYear)=0,"",SUMIFS(DataRating,DataEmployee,$A7,DataSkill,H$5,DataYear,ViewYear))) | I7: =IF(OR($A7="",I$5="",ViewYear=""),"",IF(SUMIFS(DataRating,DataEmployee,$A7,DataSkill,I$5,DataYear,ViewYear)=0,"",SUMIFS(DataRating,DataEmployee,$A7,DataSkill,I$5,DataYear,ViewYear))) | J7: =IF(OR($A7="",J$5="",ViewYear=""),"",IF(SUMIFS(DataRating,DataEmployee,$A7,DataSkill,J$5,DataYear,ViewYear)=0,"",SUMIFS(DataRating,DataEmployee,$A7,DataSkill,J$5,DataYear,ViewYear))) | K7: =IF(OR($A7="",K$5="",ViewYear=""),"",IF(SUMIFS(DataRating,DataEmployee,$A7,DataSkill,K$5,DataYear,ViewYear)=0,"",SUMIFS(DataRating,DataEmployee,$A7,DataSkill,K$5,DataYear,ViewYear))) | ... S7: =IF(OR($A7="",S$5="",ViewYear=""),"",IF(SUMIFS(DataRating,DataEmployee,$A7,DataSkill,S$5,DataYear,ViewYear)=0,"",SUMIFS(DataRating,DataEmployee,$A7,DataSkill,S$5,DataYear,ViewYear)))
A8: =IF('Employees'!B8="","",'Employees'!B8) | B8: =IF(A8="","",'Employees'!C8) | C8: =IF($A8="","",IFERROR(ROUND(AVERAGE(D8:S8),2),"")) | D8: =IF(OR($A8="",D$5="",ViewYear=""),"",IF(SUMIFS(DataRating,DataEmployee,$A8,DataSkill,D$5,DataYear,ViewYear)=0,"",SUMIFS(DataRating,DataEmployee,$A8,DataSkill,D$5,DataYear,ViewYear))) | E8: =IF(OR($A8="",E$5="",ViewYear=""),"",IF(SUMIFS(DataRating,DataEmployee,$A8,DataSkill,E$5,DataYear,ViewYear)=0,"",SUMIFS(DataRating,DataEmployee,$A8,DataSkill,E$5,DataYear,ViewYear))) | F8: =IF(OR($A8="",F$5="",ViewYear=""),"",IF(SUMIFS(DataRating,DataEmployee,$A8,DataSkill,F$5,DataYear,ViewYear)=0,"",SUMIFS(DataRating,DataEmployee,$A8,DataSkill,F$5,DataYear,ViewYear))) | G8: =IF(OR($A8="",G$5="",ViewYear=""),"",IF(SUMIFS(DataRating,DataEmployee,$A8,DataSkill,G$5,DataYear,ViewYear)=0,"",SUMIFS(DataRating,DataEmployee,$A8,DataSkill,G$5,DataYear,ViewYear))) | H8: =IF(OR($A8="",H$5="",ViewYear=""),"",IF(SUMIFS(DataRating,DataEmployee,$A8,DataSkill,H$5,DataYear,ViewYear)=0,"",SUMIFS(DataRating,DataEmployee,$A8,DataSkill,H$5,DataYear,ViewYear))) | I8: =IF(OR($A8="",I$5="",ViewYear=""),"",IF(SUMIFS(DataRating,DataEmployee,$A8,DataSkill,I$5,DataYear,ViewYear)=0,"",SUMIFS(DataRating,DataEmployee,$A8,DataSkill,I$5,DataYear,ViewYear))) | J8: =IF(OR($A8="",J$5="",ViewYear=""),"",IF(SUMIFS(DataRating,DataEmployee,$A8,DataSkill,J$5,DataYear,ViewYear)=0,"",SUMIFS(DataRating,DataEmployee,$A8,DataSkill,J$5,DataYear,ViewYear))) | K8: =IF(OR($A8="",K$5="",ViewYear=""),"",IF(SUMIFS(DataRating,DataEmployee,$A8,DataSkill,K$5,DataYear,ViewYear)=0,"",SUMIFS(DataRating,DataEmployee,$A8,DataSkill,K$5,DataYear,ViewYear))) | ... S8: =IF(OR($A8="",S$5="",ViewYear=""),"",IF(SUMIFS(DataRating,DataEmployee,$A8,DataSkill,S$5,DataYear,ViewYear)=0,"",SUMIFS(DataRating,DataEmployee,$A8,DataSkill,S$5,DataYear,ViewYear)))
A9: =IF('Employees'!B9="","",'Employees'!B9) | B9: =IF(A9="","",'Employees'!C9) | C9: =IF($A9="","",IFERROR(ROUND(AVERAGE(D9:S9),2),"")) | D9: =IF(OR($A9="",D$5="",ViewYear=""),"",IF(SUMIFS(DataRating,DataEmployee,$A9,DataSkill,D$5,DataYear,ViewYear)=0,"",SUMIFS(DataRating,DataEmployee,$A9,DataSkill,D$5,DataYear,ViewYear))) | E9: =IF(OR($A9="",E$5="",ViewYear=""),"",IF(SUMIFS(DataRating,DataEmployee,$A9,DataSkill,E$5,DataYear,ViewYear)=0,"",SUMIFS(DataRating,DataEmployee,$A9,DataSkill,E$5,DataYear,ViewYear))) | F9: =IF(OR($A9="",F$5="",ViewYear=""),"",IF(SUMIFS(DataRating,DataEmployee,$A9,DataSkill,F$5,DataYear,ViewYear)=0,"",SUMIFS(DataRating,DataEmployee,$A9,DataSkill,F$5,DataYear,ViewYear))) | G9: =IF(OR($A9="",G$5="",ViewYear=""),"",IF(SUMIFS(DataRating,DataEmployee,$A9,DataSkill,G$5,DataYear,ViewYear)=0,"",SUMIFS(DataRating,DataEmployee,$A9,DataSkill,G$5,DataYear,ViewYear))) | H9: =IF(OR($A9="",H$5="",ViewYear=""),"",IF(SUMIFS(DataRating,DataEmployee,$A9,DataSkill,H$5,DataYear,ViewYear)=0,"",SUMIFS(DataRating,DataEmployee,$A9,DataSkill,H$5,DataYear,ViewYear))) | I9: =IF(OR($A9="",I$5="",ViewYear=""),"",IF(SUMIFS(DataRating,DataEmployee,$A9,DataSkill,I$5,DataYear,ViewYear)=0,"",SUMIFS(DataRating,DataEmployee,$A9,DataSkill,I$5,DataYear,ViewYear))) | J9: =IF(OR($A9="",J$5="",ViewYear=""),"",IF(SUMIFS(DataRating,DataEmployee,$A9,DataSkill,J$5,DataYear,ViewYear)=0,"",SUMIFS(DataRating,DataEmployee,$A9,DataSkill,J$5,DataYear,ViewYear))) | K9: =IF(OR($A9="",K$5="",ViewYear=""),"",IF(SUMIFS(DataRating,DataEmployee,$A9,DataSkill,K$5,DataYear,ViewYear)=0,"",SUMIFS(DataRating,DataEmployee,$A9,DataSkill,K$5,DataYear,ViewYear))) | ... S9: =IF(OR($A9="",S$5="",ViewYear=""),"",IF(SUMIFS(DataRating,DataEmployee,$A9,DataSkill,S$5,DataYear,ViewYear)=0,"",SUMIFS(DataRating,DataEmployee,$A9,DataSkill,S$5,DataYear,ViewYear)))
A10: =IF('Employees'!B10="","",'Employees'!B10) | B10: =IF(A10="","",'Employees'!C10) | C10: =IF($A10="","",IFERROR(ROUND(AVERAGE(D10:S10),2),"")) | D10: =IF(OR($A10="",D$5="",ViewYear=""),"",IF(SUMIFS(DataRating,DataEmployee,$A10,DataSkill,D$5,DataYear,ViewYear)=0,"",SUMIFS(DataRating,DataEmployee,$A10,DataSkill,D$5,DataYear,ViewYear))) | E10: =IF(OR($A10="",E$5="",ViewYear=""),"",IF(SUMIFS(DataRating,DataEmployee,$A10,DataSkill,E$5,DataYear,ViewYear)=0,"",SUMIFS(DataRating,DataEmployee,$A10,DataSkill,E$5,DataYear,ViewYear))) | F10: =IF(OR($A10="",F$5="",ViewYear=""),"",IF(SUMIFS(DataRating,DataEmployee,$A10,DataSkill,F$5,DataYear,ViewYear)=0,"",SUMIFS(DataRating,DataEmployee,$A10,DataSkill,F$5,DataYear,ViewYear))) | G10: =IF(OR($A10="",G$5="",ViewYear=""),"",IF(SUMIFS(DataRating,DataEmployee,$A10,DataSkill,G$5,DataYear,ViewYear)=0,"",SUMIFS(DataRating,DataEmployee,$A10,DataSkill,G$5,DataYear,ViewYear))) | H10: =IF(OR($A10="",H$5="",ViewYear=""),"",IF(SUMIFS(DataRating,DataEmployee,$A10,DataSkill,H$5,DataYear,ViewYear)=0,"",SUMIFS(DataRating,DataEmployee,$A10,DataSkill,H$5,DataYear,ViewYear))) | I10: =IF(OR($A10="",I$5="",ViewYear=""),"",IF(SUMIFS(DataRating,DataEmployee,$A10,DataSkill,I$5,DataYear,ViewYear)=0,"",SUMIFS(DataRating,DataEmployee,$A10,DataSkill,I$5,DataYear,ViewYear))) | J10: =IF(OR($A10="",J$5="",ViewYear=""),"",IF(SUMIFS(DataRating,DataEmployee,$A10,DataSkill,J$5,DataYear,ViewYear)=0,"",SUMIFS(DataRating,DataEmployee,$A10,DataSkill,J$5,DataYear,ViewYear))) | K10: =IF(OR($A10="",K$5="",ViewYear=""),"",IF(SUMIFS(DataRating,DataEmployee,$A10,DataSkill,K$5,DataYear,ViewYear)=0,"",SUMIFS(DataRating,DataEmployee,$A10,DataSkill,K$5,DataYear,ViewYear))) | ... S10: =IF(OR($A10="",S$5="",ViewYear=""),"",IF(SUMIFS(DataRating,DataEmployee,$A10,DataSkill,S$5,DataYear,ViewYear)=0,"",SUMIFS(DataRating,DataEmployee,$A10,DataSkill,S$5,DataYear,ViewYear)))
A11: =IF('Employees'!B11="","",'Employees'!B11) | B11: =IF(A11="","",'Employees'!C11) | C11: =IF($A11="","",IFERROR(ROUND(AVERAGE(D11:S11),2),"")) | D11: =IF(OR($A11="",D$5="",ViewYear=""),"",IF(SUMIFS(DataRating,DataEmployee,$A11,DataSkill,D$5,DataYear,ViewYear)=0,"",SUMIFS(DataRating,DataEmployee,$A11,DataSkill,D$5,DataYear,ViewYear))) | E11: =IF(OR($A11="",E$5="",ViewYear=""),"",IF(SUMIFS(DataRating,DataEmployee,$A11,DataSkill,E$5,DataYear,ViewYear)=0,"",SUMIFS(DataRating,DataEmployee,$A11,DataSkill,E$5,DataYear,ViewYear))) | F11: =IF(OR($A11="",F$5="",ViewYear=""),"",IF(SUMIFS(DataRating,DataEmployee,$A11,DataSkill,F$5,DataYear,ViewYear)=0,"",SUMIFS(DataRating,DataEmployee,$A11,DataSkill,F$5,DataYear,ViewYear))) | G11: =IF(OR($A11="",G$5="",ViewYear=""),"",IF(SUMIFS(DataRating,DataEmployee,$A11,DataSkill,G$5,DataYear,ViewYear)=0,"",SUMIFS(DataRating,DataEmployee,$A11,DataSkill,G$5,DataYear,ViewYear))) | H11: =IF(OR($A11="",H$5="",ViewYear=""),"",IF(SUMIFS(DataRating,DataEmployee,$A11,DataSkill,H$5,DataYear,ViewYear)=0,"",SUMIFS(DataRating,DataEmployee,$A11,DataSkill,H$5,DataYear,ViewYear))) | I11: =IF(OR($A11="",I$5="",ViewYear=""),"",IF(SUMIFS(DataRating,DataEmployee,$A11,DataSkill,I$5,DataYear,ViewYear)=0,"",SUMIFS(DataRating,DataEmployee,$A11,DataSkill,I$5,DataYear,ViewYear))) | J11: =IF(OR($A11="",J$5="",ViewYear=""),"",IF(SUMIFS(DataRating,DataEmployee,$A11,DataSkill,J$5,DataYear,ViewYear)=0,"",SUMIFS(DataRating,DataEmployee,$A11,DataSkill,J$5,DataYear,ViewYear))) | K11: =IF(OR($A11="",K$5="",ViewYear=""),"",IF(SUMIFS(DataRating,DataEmployee,$A11,DataSkill,K$5,DataYear,ViewYear)=0,"",SUMIFS(DataRating,DataEmployee,$A11,DataSkill,K$5,DataYear,ViewYear))) | ... S11: =IF(OR($A11="",S$5="",ViewYear=""),"",IF(SUMIFS(DataRating,DataEmployee,$A11,DataSkill,S$5,DataYear,ViewYear)=0,"",SUMIFS(DataRating,DataEmployee,$A11,DataSkill,S$5,DataYear,ViewYear)))
A12: =IF('Employees'!B12="","",'Employees'!B12) | B12: =IF(A12="","",'Employees'!C12) | C12: =IF($A12="","",IFERROR(ROUND(AVERAGE(D12:S12),2),"")) | D12: =IF(OR($A12="",D$5="",ViewYear=""),"",IF(SUMIFS(DataRating,DataEmployee,$A12,DataSkill,D$5,DataYear,ViewYear)=0,"",SUMIFS(DataRating,DataEmployee,$A12,DataSkill,D$5,DataYear,ViewYear))) | E12: =IF(OR($A12="",E$5="",ViewYear=""),"",IF(SUMIFS(DataRating,DataEmployee,$A12,DataSkill,E$5,DataYear,ViewYear)=0,"",SUMIFS(DataRating,DataEmployee,$A12,DataSkill,E$5,DataYear,ViewYear))) | F12: =IF(OR($A12="",F$5="",ViewYear=""),"",IF(SUMIFS(DataRating,DataEmployee,$A12,DataSkill,F$5,DataYear,ViewYear)=0,"",SUMIFS(DataRating,DataEmployee,$A12,DataSkill,F$5,DataYear,ViewYear))) | G12: =IF(OR($A12="",G$5="",ViewYear=""),"",IF(SUMIFS(DataRating,DataEmployee,$A12,DataSkill,G$5,DataYear,ViewYear)=0,"",SUMIFS(DataRating,DataEmployee,$A12,DataSkill,G$5,DataYear,ViewYear))) | H12: =IF(OR($A12="",H$5="",ViewYear=""),"",IF(SUMIFS(DataRating,DataEmployee,$A12,DataSkill,H$5,DataYear,ViewYear)=0,"",SUMIFS(DataRating,DataEmployee,$A12,DataSkill,H$5,DataYear,ViewYear))) | I12: =IF(OR($A12="",I$5="",ViewYear=""),"",IF(SUMIFS(DataRating,DataEmployee,$A12,DataSkill,I$5,DataYear,ViewYear)=0,"",SUMIFS(DataRating,DataEmployee,$A12,DataSkill,I$5,DataYear,ViewYear))) | J12: =IF(OR($A12="",J$5="",ViewYear=""),"",IF(SUMIFS(DataRating,DataEmployee,$A12,DataSkill,J$5,DataYear,ViewYear)=0,"",SUMIFS(DataRating,DataEmployee,$A12,DataSkill,J$5,DataYear,ViewYear))) | K12: =IF(OR($A12="",K$5="",ViewYear=""),"",IF(SUMIFS(DataRating,DataEmployee,$A12,DataSkill,K$5,DataYear,ViewYear)=0,"",SUMIFS(DataRating,DataEmployee,$A12,DataSkill,K$5,DataYear,ViewYear))) | ... S12: =IF(OR($A12="",S$5="",ViewYear=""),"",IF(SUMIFS(DataRating,DataEmployee,$A12,DataSkill,S$5,DataYear,ViewYear)=0,"",SUMIFS(DataRating,DataEmployee,$A12,DataSkill,S$5,DataYear,ViewYear)))
A13: =IF('Employees'!B13="","",'Employees'!B13) | B13: =IF(A13="","",'Employees'!C13) | C13: =IF($A13="","",IFERROR(ROUND(AVERAGE(D13:S13),2),"")) | D13: =IF(OR($A13="",D$5="",ViewYear=""),"",IF(SUMIFS(DataRating,DataEmployee,$A13,DataSkill,D$5,DataYear,ViewYear)=0,"",SUMIFS(DataRating,DataEmployee,$A13,DataSkill,D$5,DataYear,ViewYear))) | E13: =IF(OR($A13="",E$5="",ViewYear=""),"",IF(SUMIFS(DataRating,DataEmployee,$A13,DataSkill,E$5,DataYear,ViewYear)=0,"",SUMIFS(DataRating,DataEmployee,$A13,DataSkill,E$5,DataYear,ViewYear))) | F13: =IF(OR($A13="",F$5="",ViewYear=""),"",IF(SUMIFS(DataRating,DataEmployee,$A13,DataSkill,F$5,DataYear,ViewYear)=0,"",SUMIFS(DataRating,DataEmployee,$A13,DataSkill,F$5,DataYear,ViewYear))) | G13: =IF(OR($A13="",G$5="",ViewYear=""),"",IF(SUMIFS(DataRating,DataEmployee,$A13,DataSkill,G$5,DataYear,ViewYear)=0,"",SUMIFS(DataRating,DataEmployee,$A13,DataSkill,G$5,DataYear,ViewYear))) | H13: =IF(OR($A13="",H$5="",ViewYear=""),"",IF(SUMIFS(DataRating,DataEmployee,$A13,DataSkill,H$5,DataYear,ViewYear)=0,"",SUMIFS(DataRating,DataEmployee,$A13,DataSkill,H$5,DataYear,ViewYear))) | I13: =IF(OR($A13="",I$5="",ViewYear=""),"",IF(SUMIFS(DataRating,DataEmployee,$A13,DataSkill,I$5,DataYear,ViewYear)=0,"",SUMIFS(DataRating,DataEmployee,$A13,DataSkill,I$5,DataYear,ViewYear))) | J13: =IF(OR($A13="",J$5="",ViewYear=""),"",IF(SUMIFS(DataRating,DataEmployee,$A13,DataSkill,J$5,DataYear,ViewYear)=0,"",SUMIFS(DataRating,DataEmployee,$A13,DataSkill,J$5,DataYear,ViewYear))) | K13: =IF(OR($A13="",K$5="",ViewYear=""),"",IF(SUMIFS(DataRating,DataEmployee,$A13,DataSkill,K$5,DataYear,ViewYear)=0,"",SUMIFS(DataRating,DataEmployee,$A13,DataSkill,K$5,DataYear,ViewYear))) | ... S13: =IF(OR($A13="",S$5="",ViewYear=""),"",IF(SUMIFS(DataRating,DataEmployee,$A13,DataSkill,S$5,DataYear,ViewYear)=0,"",SUMIFS(DataRating,DataEmployee,$A13,DataSkill,S$5,DataYear,ViewYear)))
A14: =IF('Employees'!B14="","",'Employees'!B14) | B14: =IF(A14="","",'Employees'!C14) | C14: =IF($A14="","",IFERROR(ROUND(AVERAGE(D14:S14),2),"")) | D14: =IF(OR($A14="",D$5="",ViewYear=""),"",IF(SUMIFS(DataRating,DataEmployee,$A14,DataSkill,D$5,DataYear,ViewYear)=0,"",SUMIFS(DataRating,DataEmployee,$A14,DataSkill,D$5,DataYear,ViewYear))) | E14: =IF(OR($A14="",E$5="",ViewYear=""),"",IF(SUMIFS(DataRating,DataEmployee,$A14,DataSkill,E$5,DataYear,ViewYear)=0,"",SUMIFS(DataRating,DataEmployee,$A14,DataSkill,E$5,DataYear,ViewYear))) | F14: =IF(OR($A14="",F$5="",ViewYear=""),"",IF(SUMIFS(DataRating,DataEmployee,$A14,DataSkill,F$5,DataYear,ViewYear)=0,"",SUMIFS(DataRating,DataEmployee,$A14,DataSkill,F$5,DataYear,ViewYear))) | G14: =IF(OR($A14="",G$5="",ViewYear=""),"",IF(SUMIFS(DataRating,DataEmployee,$A14,DataSkill,G$5,DataYear,ViewYear)=0,"",SUMIFS(DataRating,DataEmployee,$A14,DataSkill,G$5,DataYear,ViewYear))) | H14: =IF(OR($A14="",H$5="",ViewYear=""),"",IF(SUMIFS(DataRating,DataEmployee,$A14,DataSkill,H$5,DataYear,ViewYear)=0,"",SUMIFS(DataRating,DataEmployee,$A14,DataSkill,H$5,DataYear,ViewYear))) | I14: =IF(OR($A14="",I$5="",ViewYear=""),"",IF(SUMIFS(DataRating,DataEmployee,$A14,DataSkill,I$5,DataYear,ViewYear)=0,"",SUMIFS(DataRating,DataEmployee,$A14,DataSkill,I$5,DataYear,ViewYear))) | J14: =IF(OR($A14="",J$5="",ViewYear=""),"",IF(SUMIFS(DataRating,DataEmployee,$A14,DataSkill,J$5,DataYear,ViewYear)=0,"",SUMIFS(DataRating,DataEmployee,$A14,DataSkill,J$5,DataYear,ViewYear))) | K14: =IF(OR($A14="",K$5="",ViewYear=""),"",IF(SUMIFS(DataRating,DataEmployee,$A14,DataSkill,K$5,DataYear,ViewYear)=0,"",SUMIFS(DataRating,DataEmployee,$A14,DataSkill,K$5,DataYear,ViewYear))) | ... S14: =IF(OR($A14="",S$5="",ViewYear=""),"",IF(SUMIFS(DataRating,DataEmployee,$A14,DataSkill,S$5,DataYear,ViewYear)=0,"",SUMIFS(DataRating,DataEmployee,$A14,DataSkill,S$5,DataYear,ViewYear)))
A15: =IF('Employees'!B15="","",'Employees'!B15) | B15: =IF(A15="","",'Employees'!C15) | C15: =IF($A15="","",IFERROR(ROUND(AVERAGE(D15:S15),2),"")) | D15: =IF(OR($A15="",D$5="",ViewYear=""),"",IF(SUMIFS(DataRating,DataEmployee,$A15,DataSkill,D$5,DataYear,ViewYear)=0,"",SUMIFS(DataRating,DataEmployee,$A15,DataSkill,D$5,DataYear,ViewYear))) | E15: =IF(OR($A15="",E$5="",ViewYear=""),"",IF(SUMIFS(DataRating,DataEmployee,$A15,DataSkill,E$5,DataYear,ViewYear)=0,"",SUMIFS(DataRating,DataEmployee,$A15,DataSkill,E$5,DataYear,ViewYear))) | F15: =IF(OR($A15="",F$5="",ViewYear=""),"",IF(SUMIFS(DataRating,DataEmployee,$A15,DataSkill,F$5,DataYear,ViewYear)=0,"",SUMIFS(DataRating,DataEmployee,$A15,DataSkill,F$5,DataYear,ViewYear))) | G15: =IF(OR($A15="",G$5="",ViewYear=""),"",IF(SUMIFS(DataRating,DataEmployee,$A15,DataSkill,G$5,DataYear,ViewYear)=0,"",SUMIFS(DataRating,DataEmployee,$A15,DataSkill,G$5,DataYear,ViewYear))) | H15: =IF(OR($A15="",H$5="",ViewYear=""),"",IF(SUMIFS(DataRating,DataEmployee,$A15,DataSkill,H$5,DataYear,ViewYear)=0,"",SUMIFS(DataRating,DataEmployee,$A15,DataSkill,H$5,DataYear,ViewYear))) | I15: =IF(OR($A15="",I$5="",ViewYear=""),"",IF(SUMIFS(DataRating,DataEmployee,$A15,DataSkill,I$5,DataYear,ViewYear)=0,"",SUMIFS(DataRating,DataEmployee,$A15,DataSkill,I$5,DataYear,ViewYear))) | J15: =IF(OR($A15="",J$5="",ViewYear=""),"",IF(SUMIFS(DataRating,DataEmployee,$A15,DataSkill,J$5,DataYear,ViewYear)=0,"",SUMIFS(DataRating,DataEmployee,$A15,DataSkill,J$5,DataYear,ViewYear))) | K15: =IF(OR($A15="",K$5="",ViewYear=""),"",IF(SUMIFS(DataRating,DataEmployee,$A15,DataSkill,K$5,DataYear,ViewYear)=0,"",SUMIFS(DataRating,DataEmployee,$A15,DataSkill,K$5,DataYear,ViewYear))) | ... S15: =IF(OR($A15="",S$5="",ViewYear=""),"",IF(SUMIFS(DataRating,DataEmployee,$A15,DataSkill,S$5,DataYear,ViewYear)=0,"",SUMIFS(DataRating,DataEmployee,$A15,DataSkill,S$5,DataYear,ViewYear)))
A16: =IF('Employees'!B16="","",'Employees'!B16) | B16: =IF(A16="","",'Employees'!C16) | C16: =IF($A16="","",IFERROR(ROUND(AVERAGE(D16:S16),2),"")) | D16: =IF(OR($A16="",D$5="",ViewYear=""),"",IF(SUMIFS(DataRating,DataEmployee,$A16,DataSkill,D$5,DataYear,ViewYear)=0,"",SUMIFS(DataRating,DataEmployee,$A16,DataSkill,D$5,DataYear,ViewYear))) | E16: =IF(OR($A16="",E$5="",ViewYear=""),"",IF(SUMIFS(DataRating,DataEmployee,$A16,DataSkill,E$5,DataYear,ViewYear)=0,"",SUMIFS(DataRating,DataEmployee,$A16,DataSkill,E$5,DataYear,ViewYear))) | F16: =IF(OR($A16="",F$5="",ViewYear=""),"",IF(SUMIFS(DataRating,DataEmployee,$A16,DataSkill,F$5,DataYear,ViewYear)=0,"",SUMIFS(DataRating,DataEmployee,$A16,DataSkill,F$5,DataYear,ViewYear))) | G16: =IF(OR($A16="",G$5="",ViewYear=""),"",IF(SUMIFS(DataRating,DataEmployee,$A16,DataSkill,G$5,DataYear,ViewYear)=0,"",SUMIFS(DataRating,DataEmployee,$A16,DataSkill,G$5,DataYear,ViewYear))) | H16: =IF(OR($A16="",H$5="",ViewYear=""),"",IF(SUMIFS(DataRating,DataEmployee,$A16,DataSkill,H$5,DataYear,ViewYear)=0,"",SUMIFS(DataRating,DataEmployee,$A16,DataSkill,H$5,DataYear,ViewYear))) | I16: =IF(OR($A16="",I$5="",ViewYear=""),"",IF(SUMIFS(DataRating,DataEmployee,$A16,DataSkill,I$5,DataYear,ViewYear)=0,"",SUMIFS(DataRating,DataEmployee,$A16,DataSkill,I$5,DataYear,ViewYear))) | J16: =IF(OR($A16="",J$5="",ViewYear=""),"",IF(SUMIFS(DataRating,DataEmployee,$A16,DataSkill,J$5,DataYear,ViewYear)=0,"",SUMIFS(DataRating,DataEmployee,$A16,DataSkill,J$5,DataYear,ViewYear))) | K16: =IF(OR($A16="",K$5="",ViewYear=""),"",IF(SUMIFS(DataRating,DataEmployee,$A16,DataSkill,K$5,DataYear,ViewYear)=0,"",SUMIFS(DataRating,DataEmployee,$A16,DataSkill,K$5,DataYear,ViewYear))) | ... S16: =IF(OR($A16="",S$5="",ViewYear=""),"",IF(SUMIFS(DataRating,DataEmployee,$A16,DataSkill,S$5,DataYear,ViewYear)=0,"",SUMIFS(DataRating,DataEmployee,$A16,DataSkill,S$5,DataYear,ViewYear)))
A17: =IF('Employees'!B17="","",'Employees'!B17) | B17: =IF(A17="","",'Employees'!C17) | C17: =IF($A17="","",IFERROR(ROUND(AVERAGE(D17:S17),2),"")) | D17: =IF(OR($A17="",D$5="",ViewYear=""),"",IF(SUMIFS(DataRating,DataEmployee,$A17,DataSkill,D$5,DataYear,ViewYear)=0,"",SUMIFS(DataRating,DataEmployee,$A17,DataSkill,D$5,DataYear,ViewYear))) | E17: =IF(OR($A17="",E$5="",ViewYear=""),"",IF(SUMIFS(DataRating,DataEmployee,$A17,DataSkill,E$5,DataYear,ViewYear)=0,"",SUMIFS(DataRating,DataEmployee,$A17,DataSkill,E$5,DataYear,ViewYear))) | F17: =IF(OR($A17="",F$5="",ViewYear=""),"",IF(SUMIFS(DataRating,DataEmployee,$A17,DataSkill,F$5,DataYear,ViewYear)=0,"",SUMIFS(DataRating,DataEmployee,$A17,DataSkill,F$5,DataYear,ViewYear))) | G17: =IF(OR($A17="",G$5="",ViewYear=""),"",IF(SUMIFS(DataRating,DataEmployee,$A17,DataSkill,G$5,DataYear,ViewYear)=0,"",SUMIFS(DataRating,DataEmployee,$A17,DataSkill,G$5,DataYear,ViewYear))) | H17: =IF(OR($A17="",H$5="",ViewYear=""),"",IF(SUMIFS(DataRating,DataEmployee,$A17,DataSkill,H$5,DataYear,ViewYear)=0,"",SUMIFS(DataRating,DataEmployee,$A17,DataSkill,H$5,DataYear,ViewYear))) | I17: =IF(OR($A17="",I$5="",ViewYear=""),"",IF(SUMIFS(DataRating,DataEmployee,$A17,DataSkill,I$5,DataYear,ViewYear)=0,"",SUMIFS(DataRating,DataEmployee,$A17,DataSkill,I$5,DataYear,ViewYear))) | J17: =IF(OR($A17="",J$5="",ViewYear=""),"",IF(SUMIFS(DataRating,DataEmployee,$A17,DataSkill,J$5,DataYear,ViewYear)=0,"",SUMIFS(DataRating,DataEmployee,$A17,DataSkill,J$5,DataYear,ViewYear))) | K17: =IF(OR($A17="",K$5="",ViewYear=""),"",IF(SUMIFS(DataRating,DataEmployee,$A17,DataSkill,K$5,DataYear,ViewYear)=0,"",SUMIFS(DataRating,DataEmployee,$A17,DataSkill,K$5,DataYear,ViewYear))) | ... S17: =IF(OR($A17="",S$5="",ViewYear=""),"",IF(SUMIFS(DataRating,DataEmployee,$A17,DataSkill,S$5,DataYear,ViewYear)=0,"",SUMIFS(DataRating,DataEmployee,$A17,DataSkill,S$5,DataYear,ViewYear)))
... A21: =IF('Employees'!B21="","",'Employees'!B21) | B21: =IF(A21="","",'Employees'!C21) | C21: =IF($A21="","",IFERROR(ROUND(AVERAGE(D21:S21),2),"")) | D21: =IF(OR($A21="",D$5="",ViewYear=""),"",IF(SUMIFS(DataRating,DataEmployee,$A21,DataSkill,D$5,DataYear,ViewYear)=0,"",SUMIFS(DataRating,DataEmployee,$A21,DataSkill,D$5,DataYear,ViewYear))) | E21: =IF(OR($A21="",E$5="",ViewYear=""),"",IF(SUMIFS(DataRating,DataEmployee,$A21,DataSkill,E$5,DataYear,ViewYear)=0,"",SUMIFS(DataRating,DataEmployee,$A21,DataSkill,E$5,DataYear,ViewYear))) | F21: =IF(OR($A21="",F$5="",ViewYear=""),"",IF(SUMIFS(DataRating,DataEmployee,$A21,DataSkill,F$5,DataYear,ViewYear)=0,"",SUMIFS(DataRating,DataEmployee,$A21,DataSkill,F$5,DataYear,ViewYear))) | G21: =IF(OR($A21="",G$5="",ViewYear=""),"",IF(SUMIFS(DataRating,DataEmployee,$A21,DataSkill,G$5,DataYear,ViewYear)=0,"",SUMIFS(DataRating,DataEmployee,$A21,DataSkill,G$5,DataYear,ViewYear))) | H21: =IF(OR($A21="",H$5="",ViewYear=""),"",IF(SUMIFS(DataRating,DataEmployee,$A21,DataSkill,H$5,DataYear,ViewYear)=0,"",SUMIFS(DataRating,DataEmployee,$A21,DataSkill,H$5,DataYear,ViewYear))) | I21: =IF(OR($A21="",I$5="",ViewYear=""),"",IF(SUMIFS(DataRating,DataEmployee,$A21,DataSkill,I$5,DataYear,ViewYear)=0,"",SUMIFS(DataRating,DataEmployee,$A21,DataSkill,I$5,DataYear,ViewYear))) | J21: =IF(OR($A21="",J$5="",ViewYear=""),"",IF(SUMIFS(DataRating,DataEmployee,$A21,DataSkill,J$5,DataYear,ViewYear)=0,"",SUMIFS(DataRating,DataEmployee,$A21,DataSkill,J$5,DataYear,ViewYear))) | K21: =IF(OR($A21="",K$5="",ViewYear=""),"",IF(SUMIFS(DataRating,DataEmployee,$A21,DataSkill,K$5,DataYear,ViewYear)=0,"",SUMIFS(DataRating,DataEmployee,$A21,DataSkill,K$5,DataYear,ViewYear))) | ... S21: =IF(OR($A21="",S$5="",ViewYear=""),"",IF(SUMIFS(DataRating,DataEmployee,$A21,DataSkill,S$5,DataYear,ViewYear)=0,"",SUMIFS(DataRating,DataEmployee,$A21,DataSkill,S$5,DataYear,ViewYear)))
A23: Rating colour | B23: 1 | C23: 2 | D23: 3 | E23: 4 | F23: 5 | G23: 1 beginner to 5 expert. Overall = average. Gold name = highest overall this year.

Sheet Ratings
A1: ='How to Use'!A1 | C1: How to Use | D1: Skill Matrix | E1: Dashboard | F1: Employees | G1: Skills | H1: Years | I1: Lists | J1: Settings
C2: Ratings — all years | I2: Type 1-5 here for any year. This sheet is hidden in the tab bar. When you are done, right-click this tab and choose Hide.
A3: ="Rating 1-5. Current calendar year: "&CalendarYear&". Latest year with ratings: "&IF(LatestYear="","-",LatestYear)&". Filter the Employee column to focus on one person."
A5: Employee | B5: Department | C5: Skill | D5: Category | E5: =IF('Years'!B8="","",'Years'!B8) | F5: =IF('Years'!B9="","",'Years'!B9) | G5: =IF('Years'!B10="","",'Years'!B10) | H5: =IF('Years'!B11="","",'Years'!B11) | I5: =IF('Years'!B12="","",'Years'!B12) | J5: =IF('Years'!B13="","",'Years'!B13) | K5: =IF('Years'!B14="","",'Years'!B14) | L5: =IF('Years'!B15="","",'Years'!B15) | M5: =IF('Years'!B16="","",'Years'!B16) | N5: =IF('Years'!B17="","",'Years'!B17) | O5: =IF('Years'!B18="","",'Years'!B18) | P5: =IF('Years'!B19="","",'Years'!B19) | Q5: =IF('Years'!B20="","",'Years'!B20) | R5: =IF('Years'!B21="","",'Years'!B21) | S5: =IF('Years'!B22="","",'Years'!B22) | T5: =IF('Years'!B23="","",'Years'!B23) | U5: First | V5: Latest | W5: vs last year | X5: Since joined | Y5: Years rated
A6: =IF(AND('Employees'!B6<>"",'Skills'!B6<>""),'Employees'!B6,"") | B6: =IF(A6="","",'Employees'!C6) | C6: =IF(A6="","",'Skills'!B6) | D6: =IF(A6="","",'Skills'!C6) | E6: 1 | F6: 2 | G6: 3 | H6: 3 | U6: =IF(A6="","",IFERROR(INDEX(E6:T6,MATCH(TRUE,INDEX(E6:T6<>"",0),0)),"")) | V6: =IF(A6="","",IFERROR(LOOKUP(2,1/(E6:T6<>""),E6:T6),"")) | W6: =IF(OR(A6="",PreviousYear=""),"",IFERROR(LOOKUP(2,1/(E6:T6<>""),E6:T6)-INDEX(E6:T6,MATCH(PreviousYear,$E$5:$T$5,0)),"")) | X6: =IF(OR(A6="",U6="",V6=""),"",V6-U6) | Y6: =IF(A6="","",COUNT(E6:T6))
A7: =IF(AND('Employees'!B6<>"",'Skills'!B7<>""),'Employees'!B6,"") | B7: =IF(A7="","",'Employees'!C6) | C7: =IF(A7="","",'Skills'!B7) | D7: =IF(A7="","",'Skills'!C7) | E7: 2 | F7: 2 | G7: 2 | H7: 2 | U7: =IF(A7="","",IFERROR(INDEX(E7:T7,MATCH(TRUE,INDEX(E7:T7<>"",0),0)),"")) | V7: =IF(A7="","",IFERROR(LOOKUP(2,1/(E7:T7<>""),E7:T7),"")) | W7: =IF(OR(A7="",PreviousYear=""),"",IFERROR(LOOKUP(2,1/(E7:T7<>""),E7:T7)-INDEX(E7:T7,MATCH(PreviousYear,$E$5:$T$5,0)),"")) | X7: =IF(OR(A7="",U7="",V7=""),"",V7-U7) | Y7: =IF(A7="","",COUNT(E7:T7))
A8: =IF(AND('Employees'!B6<>"",'Skills'!B8<>""),'Employees'!B6,"") | B8: =IF(A8="","",'Employees'!C6) | C8: =IF(A8="","",'Skills'!B8) | D8: =IF(A8="","",'Skills'!C8) | E8: 1 | F8: 2 | G8: 2 | H8: 3 | U8: =IF(A8="","",IFERROR(INDEX(E8:T8,MATCH(TRUE,INDEX(E8:T8<>"",0),0)),"")) | V8: =IF(A8="","",IFERROR(LOOKUP(2,1/(E8:T8<>""),E8:T8),"")) | W8: =IF(OR(A8="",PreviousYear=""),"",IFERROR(LOOKUP(2,1/(E8:T8<>""),E8:T8)-INDEX(E8:T8,MATCH(PreviousYear,$E$5:$T$5,0)),"")) | X8: =IF(OR(A8="",U8="",V8=""),"",V8-U8) | Y8: =IF(A8="","",COUNT(E8:T8))
A9: =IF(AND('Employees'!B6<>"",'Skills'!B9<>""),'Employees'!B6,"") | B9: =IF(A9="","",'Employees'!C6) | C9: =IF(A9="","",'Skills'!B9) | D9: =IF(A9="","",'Skills'!C9) | E9: 2 | F9: 2 | G9: 3 | H9: 4 | U9: =IF(A9="","",IFERROR(INDEX(E9:T9,MATCH(TRUE,INDEX(E9:T9<>"",0),0)),"")) | V9: =IF(A9="","",IFERROR(LOOKUP(2,1/(E9:T9<>""),E9:T9),"")) | W9: =IF(OR(A9="",PreviousYear=""),"",IFERROR(LOOKUP(2,1/(E9:T9<>""),E9:T9)-INDEX(E9:T9,MATCH(PreviousYear,$E$5:$T$5,0)),"")) | X9: =IF(OR(A9="",U9="",V9=""),"",V9-U9) | Y9: =IF(A9="","",COUNT(E9:T9))
A10: =IF(AND('Employees'!B6<>"",'Skills'!B10<>""),'Employees'!B6,"") | B10: =IF(A10="","",'Employees'!C6) | C10: =IF(A10="","",'Skills'!B10) | D10: =IF(A10="","",'Skills'!C10) | E10: 3 | F10: 4 | G10: 4 | H10: 5 | U10: =IF(A10="","",IFERROR(INDEX(E10:T10,MATCH(TRUE,INDEX(E10:T10<>"",0),0)),"")) | V10: =IF(A10="","",IFERROR(LOOKUP(2,1/(E10:T10<>""),E10:T10),"")) | W10: =IF(OR(A10="",PreviousYear=""),"",IFERROR(LOOKUP(2,1/(E10:T10<>""),E10:T10)-INDEX(E10:T10,MATCH(PreviousYear,$E$5:$T$5,0)),"")) | X10: =IF(OR(A10="",U10="",V10=""),"",V10-U10) | Y10: =IF(A10="","",COUNT(E10:T10))
A11: =IF(AND('Employees'!B6<>"",'Skills'!B11<>""),'Employees'!B6,"") | B11: =IF(A11="","",'Employees'!C6) | C11: =IF(A11="","",'Skills'!B11) | D11: =IF(A11="","",'Skills'!C11) | E11: 3 | F11: 3 | G11: 3 | H11: 3 | U11: =IF(A11="","",IFERROR(INDEX(E11:T11,MATCH(TRUE,INDEX(E11:T11<>"",0),0)),"")) | V11: =IF(A11="","",IFERROR(LOOKUP(2,1/(E11:T11<>""),E11:T11),"")) | W11: =IF(OR(A11="",PreviousYear=""),"",IFERROR(LOOKUP(2,1/(E11:T11<>""),E11:T11)-INDEX(E11:T11,MATCH(PreviousYear,$E$5:$T$5,0)),"")) | X11: =IF(OR(A11="",U11="",V11=""),"",V11-U11) | Y11: =IF(A11="","",COUNT(E11:T11))
A12: =IF(AND('Employees'!B6<>"",'Skills'!B12<>""),'Employees'!B6,"") | B12: =IF(A12="","",'Employees'!C6) | C12: =IF(A12="","",'Skills'!B12) | D12: =IF(A12="","",'Skills'!C12) | E12: 1 | F12: 1 | G12: 2 | H12: 3 | U12: =IF(A12="","",IFERROR(INDEX(E12:T12,MATCH(TRUE,INDEX(E12:T12<>"",0),0)),"")) | V12: =IF(A12="","",IFERROR(LOOKUP(2,1/(E12:T12<>""),E12:T12),"")) | W12: =IF(OR(A12="",PreviousYear=""),"",IFERROR(LOOKUP(2,1/(E12:T12<>""),E12:T12)-INDEX(E12:T12,MATCH(PreviousYear,$E$5:$T$5,0)),"")) | X12: =IF(OR(A12="",U12="",V12=""),"",V12-U12) | Y12: =IF(A12="","",COUNT(E12:T12))
A13: =IF(AND('Employees'!B6<>"",'Skills'!B13<>""),'Employees'!B6,"") | B13: =IF(A13="","",'Employees'!C6) | C13: =IF(A13="","",'Skills'!B13) | D13: =IF(A13="","",'Skills'!C13) | E13: 3 | F13: 3 | G13: 3 | H13: 3 | U13: =IF(A13="","",IFERROR(INDEX(E13:T13,MATCH(TRUE,INDEX(E13:T13<>"",0),0)),"")) | V13: =IF(A13="","",IFERROR(LOOKUP(2,1/(E13:T13<>""),E13:T13),"")) | W13: =IF(OR(A13="",PreviousYear=""),"",IFERROR(LOOKUP(2,1/(E13:T13<>""),E13:T13)-INDEX(E13:T13,MATCH(PreviousYear,$E$5:$T$5,0)),"")) | X13: =IF(OR(A13="",U13="",V13=""),"",V13-U13) | Y13: =IF(A13="","",COUNT(E13:T13))
A14: =IF(AND('Employees'!B6<>"",'Skills'!B14<>""),'Employees'!B6,"") | B14: =IF(A14="","",'Employees'!C6) | C14: =IF(A14="","",'Skills'!B14) | D14: =IF(A14="","",'Skills'!C14) | E14: 2 | F14: 3 | G14: 3 | H14: 4 | U14: =IF(A14="","",IFERROR(INDEX(E14:T14,MATCH(TRUE,INDEX(E14:T14<>"",0),0)),"")) | V14: =IF(A14="","",IFERROR(LOOKUP(2,1/(E14:T14<>""),E14:T14),"")) | W14: =IF(OR(A14="",PreviousYear=""),"",IFERROR(LOOKUP(2,1/(E14:T14<>""),E14:T14)-INDEX(E14:T14,MATCH(PreviousYear,$E$5:$T$5,0)),"")) | X14: =IF(OR(A14="",U14="",V14=""),"",V14-U14) | Y14: =IF(A14="","",COUNT(E14:T14))
A15: =IF(AND('Employees'!B6<>"",'Skills'!B15<>""),'Employees'!B6,"") | B15: =IF(A15="","",'Employees'!C6) | C15: =IF(A15="","",'Skills'!B15) | D15: =IF(A15="","",'Skills'!C15) | E15: 1 | F15: 1 | G15: 2 | H15: 2 | U15: =IF(A15="","",IFERROR(INDEX(E15:T15,MATCH(TRUE,INDEX(E15:T15<>"",0),0)),"")) | V15: =IF(A15="","",IFERROR(LOOKUP(2,1/(E15:T15<>""),E15:T15),"")) | W15: =IF(OR(A15="",PreviousYear=""),"",IFERROR(LOOKUP(2,1/(E15:T15<>""),E15:T15)-INDEX(E15:T15,MATCH(PreviousYear,$E$5:$T$5,0)),"")) | X15: =IF(OR(A15="",U15="",V15=""),"",V15-U15) | Y15: =IF(A15="","",COUNT(E15:T15))
A16: =IF(AND('Employees'!B6<>"",'Skills'!B16<>""),'Employees'!B6,"") | B16: =IF(A16="","",'Employees'!C6) | C16: =IF(A16="","",'Skills'!B16) | D16: =IF(A16="","",'Skills'!C16) | E16: 2 | F16: 3 | G16: 3 | H16: 4 | U16: =IF(A16="","",IFERROR(INDEX(E16:T16,MATCH(TRUE,INDEX(E16:T16<>"",0),0)),"")) | V16: =IF(A16="","",IFERROR(LOOKUP(2,1/(E16:T16<>""),E16:T16),"")) | W16: =IF(OR(A16="",PreviousYear=""),"",IFERROR(LOOKUP(2,1/(E16:T16<>""),E16:T16)-INDEX(E16:T16,MATCH(PreviousYear,$E$5:$T$5,0)),"")) | X16: =IF(OR(A16="",U16="",V16=""),"",V16-U16) | Y16: =IF(A16="","",COUNT(E16:T16))
A17: =IF(AND('Employees'!B6<>"",'Skills'!B17<>""),'Employees'!B6,"") | B17: =IF(A17="","",'Employees'!C6) | C17: =IF(A17="","",'Skills'!B17) | D17: =IF(A17="","",'Skills'!C17) | U17: =IF(A17="","",IFERROR(INDEX(E17:T17,MATCH(TRUE,INDEX(E17:T17<>"",0),0)),"")) | V17: =IF(A17="","",IFERROR(LOOKUP(2,1/(E17:T17<>""),E17:T17),"")) | W17: =IF(OR(A17="",PreviousYear=""),"",IFERROR(LOOKUP(2,1/(E17:T17<>""),E17:T17)-INDEX(E17:T17,MATCH(PreviousYear,$E$5:$T$5,0)),"")) | X17: =IF(OR(A17="",U17="",V17=""),"",V17-U17) | Y17: =IF(A17="","",COUNT(E17:T17))
A18: =IF(AND('Employees'!B6<>"",'Skills'!B18<>""),'Employees'!B6,"") | B18: =IF(A18="","",'Employees'!C6) | C18: =IF(A18="","",'Skills'!B18) | D18: =IF(A18="","",'Skills'!C18) | U18: =IF(A18="","",IFERROR(INDEX(E18:T18,MATCH(TRUE,INDEX(E18:T18<>"",0),0)),"")) | V18: =IF(A18="","",IFERROR(LOOKUP(2,1/(E18:T18<>""),E18:T18),"")) | W18: =IF(OR(A18="",PreviousYear=""),"",IFERROR(LOOKUP(2,1/(E18:T18<>""),E18:T18)-INDEX(E18:T18,MATCH(PreviousYear,$E$5:$T$5,0)),"")) | X18: =IF(OR(A18="",U18="",V18=""),"",V18-U18) | Y18: =IF(A18="","",COUNT(E18:T18))
A19: =IF(AND('Employees'!B6<>"",'Skills'!B19<>""),'Employees'!B6,"") | B19: =IF(A19="","",'Employees'!C6) | C19: =IF(A19="","",'Skills'!B19) | D19: =IF(A19="","",'Skills'!C19) | U19: =IF(A19="","",IFERROR(INDEX(E19:T19,MATCH(TRUE,INDEX(E19:T19<>"",0),0)),"")) | V19: =IF(A19="","",IFERROR(LOOKUP(2,1/(E19:T19<>""),E19:T19),"")) | W19: =IF(OR(A19="",PreviousYear=""),"",IFERROR(LOOKUP(2,1/(E19:T19<>""),E19:T19)-INDEX(E19:T19,MATCH(PreviousYear,$E$5:$T$5,0)),"")) | X19: =IF(OR(A19="",U19="",V19=""),"",V19-U19) | Y19: =IF(A19="","",COUNT(E19:T19))
A20: =IF(AND('Employees'!B6<>"",'Skills'!B20<>""),'Employees'!B6,"") | B20: =IF(A20="","",'Employees'!C6) | C20: =IF(A20="","",'Skills'!B20) | D20: =IF(A20="","",'Skills'!C20) | U20: =IF(A20="","",IFERROR(INDEX(E20:T20,MATCH(TRUE,INDEX(E20:T20<>"",0),0)),"")) | V20: =IF(A20="","",IFERROR(LOOKUP(2,1/(E20:T20<>""),E20:T20),"")) | W20: =IF(OR(A20="",PreviousYear=""),"",IFERROR(LOOKUP(2,1/(E20:T20<>""),E20:T20)-INDEX(E20:T20,MATCH(PreviousYear,$E$5:$T$5,0)),"")) | X20: =IF(OR(A20="",U20="",V20=""),"",V20-U20) | Y20: =IF(A20="","",COUNT(E20:T20))
A21: =IF(AND('Employees'!B6<>"",'Skills'!B21<>""),'Employees'!B6,"") | B21: =IF(A21="","",'Employees'!C6) | C21: =IF(A21="","",'Skills'!B21) | D21: =IF(A21="","",'Skills'!C21) | U21: =IF(A21="","",IFERROR(INDEX(E21:T21,MATCH(TRUE,INDEX(E21:T21<>"",0),0)),"")) | V21: =IF(A21="","",IFERROR(LOOKUP(2,1/(E21:T21<>""),E21:T21),"")) | W21: =IF(OR(A21="",PreviousYear=""),"",IFERROR(LOOKUP(2,1/(E21:T21<>""),E21:T21)-INDEX(E21:T21,MATCH(PreviousYear,$E$5:$T$5,0)),"")) | X21: =IF(OR(A21="",U21="",V21=""),"",V21-U21) | Y21: =IF(A21="","",COUNT(E21:T21))
A22: =IF(AND('Employees'!B7<>"",'Skills'!B6<>""),'Employees'!B7,"") | B22: =IF(A22="","",'Employees'!C7) | C22: =IF(A22="","",'Skills'!B6) | D22: =IF(A22="","",'Skills'!C6) | E22: 5 | F22: 5 | G22: 5 | H22: 5 | U22: =IF(A22="","",IFERROR(INDEX(E22:T22,MATCH(TRUE,INDEX(E22:T22<>"",0),0)),"")) | V22: =IF(A22="","",IFERROR(LOOKUP(2,1/(E22:T22<>""),E22:T22),"")) | W22: =IF(OR(A22="",PreviousYear=""),"",IFERROR(LOOKUP(2,1/(E22:T22<>""),E22:T22)-INDEX(E22:T22,MATCH(PreviousYear,$E$5:$T$5,0)),"")) | X22: =IF(OR(A22="",U22="",V22=""),"",V22-U22) | Y22: =IF(A22="","",COUNT(E22:T22))
A23: =IF(AND('Employees'!B7<>"",'Skills'!B7<>""),'Employees'!B7,"") | B23: =IF(A23="","",'Employees'!C7) | C23: =IF(A23="","",'Skills'!B7) | D23: =IF(A23="","",'Skills'!C7) | E23: 3 | F23: 4 | G23: 4 | H23: 4 | U23: =IF(A23="","",IFERROR(INDEX(E23:T23,MATCH(TRUE,INDEX(E23:T23<>"",0),0)),"")) | V23: =IF(A23="","",IFERROR(LOOKUP(2,1/(E23:T23<>""),E23:T23),"")) | W23: =IF(OR(A23="",PreviousYear=""),"",IFERROR(LOOKUP(2,1/(E23:T23<>""),E23:T23)-INDEX(E23:T23,MATCH(PreviousYear,$E$5:$T$5,0)),"")) | X23: =IF(OR(A23="",U23="",V23=""),"",V23-U23) | Y23: =IF(A23="","",COUNT(E23:T23))
A24: =IF(AND('Employees'!B7<>"",'Skills'!B8<>""),'Employees'!B7,"") | B24: =IF(A24="","",'Employees'!C7) | C24: =IF(A24="","",'Skills'!B8) | D24: =IF(A24="","",'Skills'!C8) | E24: 3 | F24: 3 | G24: 4 | H24: 5 | U24: =IF(A24="","",IFERROR(INDEX(E24:T24,MATCH(TRUE,INDEX(E24:T24<>"",0),0)),"")) | V24: =IF(A24="","",IFERROR(LOOKUP(2,1/(E24:T24<>""),E24:T24),"")) | W24: =IF(OR(A24="",PreviousYear=""),"",IFERROR(LOOKUP(2,1/(E24:T24<>""),E24:T24)-INDEX(E24:T24,MATCH(PreviousYear,$E$5:$T$5,0)),"")) | X24: =IF(OR(A24="",U24="",V24=""),"",V24-U24) | Y24: =IF(A24="","",COUNT(E24:T24))
A25: =IF(AND('Employees'!B7<>"",'Skills'!B9<>""),'Employees'!B7,"") | B25: =IF(A25="","",'Employees'!C7) | C25: =IF(A25="","",'Skills'!B9) | D25: =IF(A25="","",'Skills'!C9) | E25: 1 | F25: 2 | G25: 2 | H25: 3 | U25: =IF(A25="","",IFERROR(INDEX(E25:T25,MATCH(TRUE,INDEX(E25:T25<>"",0),0)),"")) | V25: =IF(A25="","",IFERROR(LOOKUP(2,1/(E25:T25<>""),E25:T25),"")) | W25: =IF(OR(A25="",PreviousYear=""),"",IFERROR(LOOKUP(2,1/(E25:T25<>""),E25:T25)-INDEX(E25:T25,MATCH(PreviousYear,$E$5:$T$5,0)),"")) | X25: =IF(OR(A25="",U25="",V25=""),"",V25-U25) | Y25: =IF(A25="","",COUNT(E25:T25))
A26: =IF(AND('Employees'!B7<>"",'Skills'!B10<>""),'Employees'!B7,"") | B26: =IF(A26="","",'Employees'!C7) | C26: =IF(A26="","",'Skills'!B10) | D26: =IF(A26="","",'Skills'!C10) | E26: 2 | F26: 2 | G26: 2 | H26: 2 | U26: =IF(A26="","",IFERROR(INDEX(E26:T26,MATCH(TRUE,INDEX(E26:T26<>"",0),0)),"")) | V26: =IF(A26="","",IFERROR(LOOKUP(2,1/(E26:T26<>""),E26:T26),"")) | W26: =IF(OR(A26="",PreviousYear=""),"",IFERROR(LOOKUP(2,1/(E26:T26<>""),E26:T26)-INDEX(E26:T26,MATCH(PreviousYear,$E$5:$T$5,0)),"")) | X26: =IF(OR(A26="",U26="",V26=""),"",V26-U26) | Y26: =IF(A26="","",COUNT(E26:T26))
A27: =IF(AND('Employees'!B7<>"",'Skills'!B11<>""),'Employees'!B7,"") | B27: =IF(A27="","",'Employees'!C7) | C27: =IF(A27="","",'Skills'!B11) | D27: =IF(A27="","",'Skills'!C11) | E27: 3 | F27: 4 | G27: 5 | H27: 5 | U27: =IF(A27="","",IFERROR(INDEX(E27:T27,MATCH(TRUE,INDEX(E27:T27<>"",0),0)),"")) | V27: =IF(A27="","",IFERROR(LOOKUP(2,1/(E27:T27<>""),E27:T27),"")) | W27: =IF(OR(A27="",PreviousYear=""),"",IFERROR(LOOKUP(2,1/(E27:T27<>""),E27:T27)-INDEX(E27:T27,MATCH(PreviousYear,$E$5:$T$5,0)),"")) | X27: =IF(OR(A27="",U27="",V27=""),"",V27-U27) | Y27: =IF(A27="","",COUNT(E27:T27))
A28: =IF(AND('Employees'!B7<>"",'Skills'!B12<>""),'Employees'!B7,"") | B28: =IF(A28="","",'Employees'!C7) | C28: =IF(A28="","",'Skills'!B12) | D28: =IF(A28="","",'Skills'!C12) | E28: 2 | F28: 2 | G28: 2 | H28: 3 | U28: =IF(A28="","",IFERROR(INDEX(E28:T28,MATCH(TRUE,INDEX(E28:T28<>"",0),0)),"")) | V28: =IF(A28="","",IFERROR(LOOKUP(2,1/(E28:T28<>""),E28:T28),"")) | W28: =IF(OR(A28="",PreviousYear=""),"",IFERROR(LOOKUP(2,1/(E28:T28<>""),E28:T28)-INDEX(E28:T28,MATCH(PreviousYear,$E$5:$T$5,0)),"")) | X28: =IF(OR(A28="",U28="",V28=""),"",V28-U28) | Y28: =IF(A28="","",COUNT(E28:T28))
A29: =IF(AND('Employees'!B7<>"",'Skills'!B13<>""),'Employees'!B7,"") | B29: =IF(A29="","",'Employees'!C7) | C29: =IF(A29="","",'Skills'!B13) | D29: =IF(A29="","",'Skills'!C13) | E29: 1 | F29: 2 | G29: 2 | H29: 3 | U29: =IF(A29="","",IFERROR(INDEX(E29:T29,MATCH(TRUE,INDEX(E29:T29<>"",0),0)),"")) | V29: =IF(A29="","",IFERROR(LOOKUP(2,1/(E29:T29<>""),E29:T29),"")) | W29: =IF(OR(A29="",PreviousYear=""),"",IFERROR(LOOKUP(2,1/(E29:T29<>""),E29:T29)-INDEX(E29:T29,MATCH(PreviousYear,$E$5:$T$5,0)),"")) | X29: =IF(OR(A29="",U29="",V29=""),"",V29-U29) | Y29: =IF(A29="","",COUNT(E29:T29))
A30: =IF(AND('Employees'!B7<>"",'Skills'!B14<>""),'Employees'!B7,"") | B30: =IF(A30="","",'Employees'!C7) | C30: =IF(A30="","",'Skills'!B14) | D30: =IF(A30="","",'Skills'!C14) | E30: 2 | F30: 2 | G30: 3 | H30: 3 | U30: =IF(A30="","",IFERROR(INDEX(E30:T30,MATCH(TRUE,INDEX(E30:T30<>"",0),0)),"")) | V30: =IF(A30="","",IFERROR(LOOKUP(2,1/(E30:T30<>""),E30:T30),"")) | W30: =IF(OR(A30="",PreviousYear=""),"",IFERROR(LOOKUP(2,1/(E30:T30<>""),E30:T30)-INDEX(E30:T30,MATCH(PreviousYear,$E$5:$T$5,0)),"")) | X30: =IF(OR(A30="",U30="",V30=""),"",V30-U30) | Y30: =IF(A30="","",COUNT(E30:T30))
A31: =IF(AND('Employees'!B7<>"",'Skills'!B15<>""),'Employees'!B7,"") | B31: =IF(A31="","",'Employees'!C7) | C31: =IF(A31="","",'Skills'!B15) | D31: =IF(A31="","",'Skills'!C15) | E31: 1 | F31: 2 | G31: 2 | H31: 2 | U31: =IF(A31="","",IFERROR(INDEX(E31:T31,MATCH(TRUE,INDEX(E31:T31<>"",0),0)),"")) | V31: =IF(A31="","",IFERROR(LOOKUP(2,1/(E31:T31<>""),E31:T31),"")) | W31: =IF(OR(A31="",PreviousYear=""),"",IFERROR(LOOKUP(2,1/(E31:T31<>""),E31:T31)-INDEX(E31:T31,MATCH(PreviousYear,$E$5:$T$5,0)),"")) | X31: =IF(OR(A31="",U31="",V31=""),"",V31-U31) | Y31: =IF(A31="","",COUNT(E31:T31))
A32: =IF(AND('Employees'!B7<>"",'Skills'!B16<>""),'Employees'!B7,"") | B32: =IF(A32="","",'Employees'!C7) | C32: =IF(A32="","",'Skills'!B16) | D32: =IF(A32="","",'Skills'!C16) | E32: 4 | F32: 4 | G32: 4 | H32: 4 | U32: =IF(A32="","",IFERROR(INDEX(E32:T32,MATCH(TRUE,INDEX(E32:T32<>"",0),0)),"")) | V32: =IF(A32="","",IFERROR(LOOKUP(2,1/(E32:T32<>""),E32:T32),"")) | W32: =IF(OR(A32="",PreviousYear=""),"",IFERROR(LOOKUP(2,1/(E32:T32<>""),E32:T32)-INDEX(E32:T32,MATCH(PreviousYear,$E$5:$T$5,0)),"")) | X32: =IF(OR(A32="",U32="",V32=""),"",V32-U32) | Y32: =IF(A32="","",COUNT(E32:T32))
A33: =IF(AND('Employees'!B7<>"",'Skills'!B17<>""),'Employees'!B7,"") | B33: =IF(A33="","",'Employees'!C7) | C33: =IF(A33="","",'Skills'!B17) | D33: =IF(A33="","",'Skills'!C17) | U33: =IF(A33="","",IFERROR(INDEX(E33:T33,MATCH(TRUE,INDEX(E33:T33<>"",0),0)),"")) | V33: =IF(A33="","",IFERROR(LOOKUP(2,1/(E33:T33<>""),E33:T33),"")) | W33: =IF(OR(A33="",PreviousYear=""),"",IFERROR(LOOKUP(2,1/(E33:T33<>""),E33:T33)-INDEX(E33:T33,MATCH(PreviousYear,$E$5:$T$5,0)),"")) | X33: =IF(OR(A33="",U33="",V33=""),"",V33-U33) | Y33: =IF(A33="","",COUNT(E33:T33))
A34: =IF(AND('Employees'!B7<>"",'Skills'!B18<>""),'Employees'!B7,"") | B34: =IF(A34="","",'Employees'!C7) | C34: =IF(A34="","",'Skills'!B18) | D34: =IF(A34="","",'Skills'!C18) | U34: =IF(A34="","",IFERROR(INDEX(E34:T34,MATCH(TRUE,INDEX(E34:T34<>"",0),0)),"")) | V34: =IF(A34="","",IFERROR(LOOKUP(2,1/(E34:T34<>""),E34:T34),"")) | W34: =IF(OR(A34="",PreviousYear=""),"",IFERROR(LOOKUP(2,1/(E34:T34<>""),E34:T34)-INDEX(E34:T34,MATCH(PreviousYear,$E$5:$T$5,0)),"")) | X34: =IF(OR(A34="",U34="",V34=""),"",V34-U34) | Y34: =IF(A34="","",COUNT(E34:T34))
A35: =IF(AND('Employees'!B7<>"",'Skills'!B19<>""),'Employees'!B7,"") | B35: =IF(A35="","",'Employees'!C7) | C35: =IF(A35="","",'Skills'!B19) | D35: =IF(A35="","",'Skills'!C19) | U35: =IF(A35="","",IFERROR(INDEX(E35:T35,MATCH(TRUE,INDEX(E35:T35<>"",0),0)),"")) | V35: =IF(A35="","",IFERROR(LOOKUP(2,1/(E35:T35<>""),E35:T35),"")) | W35: =IF(OR(A35="",PreviousYear=""),"",IFERROR(LOOKUP(2,1/(E35:T35<>""),E35:T35)-INDEX(E35:T35,MATCH(PreviousYear,$E$5:$T$5,0)),"")) | X35: =IF(OR(A35="",U35="",V35=""),"",V35-U35) | Y35: =IF(A35="","",COUNT(E35:T35))
A36: =IF(AND('Employees'!B7<>"",'Skills'!B20<>""),'Employees'!B7,"") | B36: =IF(A36="","",'Employees'!C7) | C36: =IF(A36="","",'Skills'!B20) | D36: =IF(A36="","",'Skills'!C20) | U36: =IF(A36="","",IFERROR(INDEX(E36:T36,MATCH(TRUE,INDEX(E36:T36<>"",0),0)),"")) | V36: =IF(A36="","",IFERROR(LOOKUP(2,1/(E36:T36<>""),E36:T36),"")) | W36: =IF(OR(A36="",PreviousYear=""),"",IFERROR(LOOKUP(2,1/(E36:T36<>""),E36:T36)-INDEX(E36:T36,MATCH(PreviousYear,$E$5:$T$5,0)),"")) | X36: =IF(OR(A36="",U36="",V36=""),"",V36-U36) | Y36: =IF(A36="","",COUNT(E36:T36))
A37: =IF(AND('Employees'!B7<>"",'Skills'!B21<>""),'Employees'!B7,"") | B37: =IF(A37="","",'Employees'!C7) | C37: =IF(A37="","",'Skills'!B21) | D37: =IF(A37="","",'Skills'!C21) | U37: =IF(A37="","",IFERROR(INDEX(E37:T37,MATCH(TRUE,INDEX(E37:T37<>"",0),0)),"")) | V37: =IF(A37="","",IFERROR(LOOKUP(2,1/(E37:T37<>""),E37:T37),"")) | W37: =IF(OR(A37="",PreviousYear=""),"",IFERROR(LOOKUP(2,1/(E37:T37<>""),E37:T37)-INDEX(E37:T37,MATCH(PreviousYear,$E$5:$T$5,0)),"")) | X37: =IF(OR(A37="",U37="",V37=""),"",V37-U37) | Y37: =IF(A37="","",COUNT(E37:T37))
A38: =IF(AND('Employees'!B8<>"",'Skills'!B6<>""),'Employees'!B8,"") | B38: =IF(A38="","",'Employees'!C8) | C38: =IF(A38="","",'Skills'!B6) | D38: =IF(A38="","",'Skills'!C6) | E38: 1 | F38: 2 | G38: 2 | H38: 3 | U38: =IF(A38="","",IFERROR(INDEX(E38:T38,MATCH(TRUE,INDEX(E38:T38<>"",0),0)),"")) | V38: =IF(A38="","",IFERROR(LOOKUP(2,1/(E38:T38<>""),E38:T38),"")) | W38: =IF(OR(A38="",PreviousYear=""),"",IFERROR(LOOKUP(2,1/(E38:T38<>""),E38:T38)-INDEX(E38:T38,MATCH(PreviousYear,$E$5:$T$5,0)),"")) | X38: =IF(OR(A38="",U38="",V38=""),"",V38-U38) | Y38: =IF(A38="","",COUNT(E38:T38))
A39: =IF(AND('Employees'!B8<>"",'Skills'!B7<>""),'Employees'!B8,"") | B39: =IF(A39="","",'Employees'!C8) | C39: =IF(A39="","",'Skills'!B7) | D39: =IF(A39="","",'Skills'!C7) | E39: 1 | F39: 1 | G39: 2 | H39: 2 | U39: =IF(A39="","",IFERROR(INDEX(E39:T39,MATCH(TRUE,INDEX(E39:T39<>"",0),0)),"")) | V39: =IF(A39="","",IFERROR(LOOKUP(2,1/(E39:T39<>""),E39:T39),"")) | W39: =IF(OR(A39="",PreviousYear=""),"",IFERROR(LOOKUP(2,1/(E39:T39<>""),E39:T39)-INDEX(E39:T39,MATCH(PreviousYear,$E$5:$T$5,0)),"")) | X39: =IF(OR(A39="",U39="",V39=""),"",V39-U39) | Y39: =IF(A39="","",COUNT(E39:T39))
A40: =IF(AND('Employees'!B8<>"",'Skills'!B8<>""),'Employees'!B8,"") | B40: =IF(A40="","",'Employees'!C8) | C40: =IF(A40="","",'Skills'!B8) | D40: =IF(A40="","",'Skills'!C8) | E40: 1 | F40: 2 | G40: 2 | H40: 2 | U40: =IF(A40="","",IFERROR(INDEX(E40:T40,MATCH(TRUE,INDEX(E40:T40<>"",0),0)),"")) | V40: =IF(A40="","",IFERROR(LOOKUP(2,1/(E40:T40<>""),E40:T40),"")) | W40: =IF(OR(A40="",PreviousYear=""),"",IFERROR(LOOKUP(2,1/(E40:T40<>""),E40:T40)-INDEX(E40:T40,MATCH(PreviousYear,$E$5:$T$5,0)),"")) | X40: =IF(OR(A40="",U40="",V40=""),"",V40-U40) | Y40: =IF(A40="","",COUNT(E40:T40))
A41: =IF(AND('Employees'!B8<>"",'Skills'!B9<>""),'Employees'!B8,"") | B41: =IF(A41="","",'Employees'!C8) | C41: =IF(A41="","",'Skills'!B9) | D41: =IF(A41="","",'Skills'!C9) | E41: 4 | F41: 4 | G41: 4 | H41: 5 | U41: =IF(A41="","",IFERROR(INDEX(E41:T41,MATCH(TRUE,INDEX(E41:T41<>"",0),0)),"")) | V41: =IF(A41="","",IFERROR(LOOKUP(2,1/(E41:T41<>""),E41:T41),"")) | W41: =IF(OR(A41="",PreviousYear=""),"",IFERROR(LOOKUP(2,1/(E41:T41<>""),E41:T41)-INDEX(E41:T41,MATCH(PreviousYear,$E$5:$T$5,0)),"")) | X41: =IF(OR(A41="",U41="",V41=""),"",V41-U41) | Y41: =IF(A41="","",COUNT(E41:T41))
...

Sheet Dashboard
A1: ='How to Use'!A1 | C1: How to Use | D1: Skill Matrix | E1: Dashboard | F1: Employees | G1: Skills | H1: Years | I1: Lists | J1: Settings
C2: Dashboard
A3: Look at Team, Skillsets, or Individual, then From year and To year. The Skillset dropdown is the job to fill: switch Look at to Skillsets and everyone is ranked on that skill. Top row is the best candidate.
A5: Look at | B5: Team | C5: From year | D5: 2023 | E5: To year | F5: 2026
A6: Department | B6: (All departments) | C6: Skillset | D6: Broadcast Camera Operation | E6: Employee | F6: Alex Rivera | G6: Team uses Department. Skillsets uses Skillset (who can do that job). Individual uses Employee.
A7: =IF(ViewMode="Team","Team: year-on-year overall ratings"&IF(DeptFilter="(All departments)",""," | "&DeptFilter)&" ("&DashFromYear&" vs "&DashToYear&")",IF(ViewMode="Skillsets","Who is the best candidate for the job: "&SkillSetFilter&" ("&DashFromYear&" vs "&DashToYear&")","Individual: "&EmpFilter&" vs themselves ("&DashFromYear&" vs "&DashToYear&")"))
A8: =IF(ViewMode="Team","Year",IF(ViewMode="Skillsets","Rank","Skillset")) | B8: =IF(ViewMode="Team","Overall rating",IF(ViewMode="Skillsets","Employee","From")) | C8: =IF(ViewMode="Team","Change vs prior year",IF(ViewMode="Skillsets","Department","To")) | D8: =IF(ViewMode="Skillsets",DashFromYear,IF(ViewMode="Individual","Change","")) | E8: =IF(ViewMode="Skillsets",DashToYear,"") | F8: =IF(ViewMode="Skillsets","Change","")
A9: =IF(ViewMode="Team",IF(Calc!A5="","",Calc!A5),IF(ViewMode="Skillsets",IF(Calc!S8="","",1),IF(Calc!G5="","",Calc!G5))) | B9: =IF(ViewMode="Team",IF(A9="","",IF(ISNA(Calc!B5),"",Calc!B5)),IF(ViewMode="Skillsets",IF(A9="","",Calc!S8),IF(A9="","",IF(Calc!H5="","",Calc!H5)))) | C9: =IF(ViewMode="Team",IF(OR(A9="",B9="",NOT(ISNUMBER(B9)),NOT(ISNUMBER(B8))),"",B9-B8),IF(ViewMode="Skillsets",IF(B9="","",IFERROR(INDEX(Employees!C6:C21,MATCH(B9,Employees!B6:B21,0)),"")),IF(A9="","",IF(Calc!I5="","",Calc!I5)))) | D9: =IF(ViewMode="Skillsets",IF(B9="","",IFERROR(INDEX(Calc!N8:N23,MATCH(B9,Calc!L8:L23,0)),"")),IF(ViewMode="Individual",IF(OR(B9="",C9=""),"",C9-B9),"")) | E9: =IF(ViewMode<>"Skillsets","",IF(B9="","",Calc!T8)) | F9: =IF(ViewMode<>"Skillsets","",IF(OR(D9="",E9=""),"",E9-D9))
A10: =IF(ViewMode="Team",IF(Calc!A6="","",Calc!A6),IF(ViewMode="Skillsets",IF(Calc!S9="","",2),IF(Calc!G6="","",Calc!G6))) | B10: =IF(ViewMode="Team",IF(A10="","",IF(ISNA(Calc!B6),"",Calc!B6)),IF(ViewMode="Skillsets",IF(A10="","",Calc!S9),IF(A10="","",IF(Calc!H6="","",Calc!H6)))) | C10: =IF(ViewMode="Team",IF(OR(A10="",B10="",NOT(ISNUMBER(B10)),NOT(ISNUMBER(B9))),"",B10-B9),IF(ViewMode="Skillsets",IF(B10="","",IFERROR(INDEX(Employees!C6:C21,MATCH(B10,Employees!B6:B21,0)),"")),IF(A10="","",IF(Calc!I6="","",Calc!I6)))) | D10: =IF(ViewMode="Skillsets",IF(B10="","",IFERROR(INDEX(Calc!N8:N23,MATCH(B10,Calc!L8:L23,0)),"")),IF(ViewMode="Individual",IF(OR(B10="",C10=""),"",C10-B10),"")) | E10: =IF(ViewMode<>"Skillsets","",IF(B10="","",Calc!T9)) | F10: =IF(ViewMode<>"Skillsets","",IF(OR(D10="",E10=""),"",E10-D10))
A11: =IF(ViewMode="Team",IF(Calc!A7="","",Calc!A7),IF(ViewMode="Skillsets",IF(Calc!S10="","",3),IF(Calc!G7="","",Calc!G7))) | B11: =IF(ViewMode="Team",IF(A11="","",IF(ISNA(Calc!B7),"",Calc!B7)),IF(ViewMode="Skillsets",IF(A11="","",Calc!S10),IF(A11="","",IF(Calc!H7="","",Calc!H7)))) | C11: =IF(ViewMode="Team",IF(OR(A11="",B11="",NOT(ISNUMBER(B11)),NOT(ISNUMBER(B10))),"",B11-B10),IF(ViewMode="Skillsets",IF(B11="","",IFERROR(INDEX(Employees!C6:C21,MATCH(B11,Employees!B6:B21,0)),"")),IF(A11="","",IF(Calc!I7="","",Calc!I7)))) | D11: =IF(ViewMode="Skillsets",IF(B11="","",IFERROR(INDEX(Calc!N8:N23,MATCH(B11,Calc!L8:L23,0)),"")),IF(ViewMode="Individual",IF(OR(B11="",C11=""),"",C11-B11),"")) | E11: =IF(ViewMode<>"Skillsets","",IF(B11="","",Calc!T10)) | F11: =IF(ViewMode<>"Skillsets","",IF(OR(D11="",E11=""),"",E11-D11))
A12: =IF(ViewMode="Team",IF(Calc!A8="","",Calc!A8),IF(ViewMode="Skillsets",IF(Calc!S11="","",4),IF(Calc!G8="","",Calc!G8))) | B12: =IF(ViewMode="Team",IF(A12="","",IF(ISNA(Calc!B8),"",Calc!B8)),IF(ViewMode="Skillsets",IF(A12="","",Calc!S11),IF(A12="","",IF(Calc!H8="","",Calc!H8)))) | C12: =IF(ViewMode="Team",IF(OR(A12="",B12="",NOT(ISNUMBER(B12)),NOT(ISNUMBER(B11))),"",B12-B11),IF(ViewMode="Skillsets",IF(B12="","",IFERROR(INDEX(Employees!C6:C21,MATCH(B12,Employees!B6:B21,0)),"")),IF(A12="","",IF(Calc!I8="","",Calc!I8)))) | D12: =IF(ViewMode="Skillsets",IF(B12="","",IFERROR(INDEX(Calc!N8:N23,MATCH(B12,Calc!L8:L23,0)),"")),IF(ViewMode="Individual",IF(OR(B12="",C12=""),"",C12-B12),"")) | E12: =IF(ViewMode<>"Skillsets","",IF(B12="","",Calc!T11)) | F12: =IF(ViewMode<>"Skillsets","",IF(OR(D12="",E12=""),"",E12-D12))
A13: =IF(ViewMode="Team",IF(Calc!A9="","",Calc!A9),IF(ViewMode="Skillsets",IF(Calc!S12="","",5),IF(Calc!G9="","",Calc!G9))) | B13: =IF(ViewMode="Team",IF(A13="","",IF(ISNA(Calc!B9),"",Calc!B9)),IF(ViewMode="Skillsets",IF(A13="","",Calc!S12),IF(A13="","",IF(Calc!H9="","",Calc!H9)))) | C13: =IF(ViewMode="Team",IF(OR(A13="",B13="",NOT(ISNUMBER(B13)),NOT(ISNUMBER(B12))),"",B13-B12),IF(ViewMode="Skillsets",IF(B13="","",IFERROR(INDEX(Employees!C6:C21,MATCH(B13,Employees!B6:B21,0)),"")),IF(A13="","",IF(Calc!I9="","",Calc!I9)))) | D13: =IF(ViewMode="Skillsets",IF(B13="","",IFERROR(INDEX(Calc!N8:N23,MATCH(B13,Calc!L8:L23,0)),"")),IF(ViewMode="Individual",IF(OR(B13="",C13=""),"",C13-B13),"")) | E13: =IF(ViewMode<>"Skillsets","",IF(B13="","",Calc!T12)) | F13: =IF(ViewMode<>"Skillsets","",IF(OR(D13="",E13=""),"",E13-D13))
A14: =IF(ViewMode="Team",IF(Calc!A10="","",Calc!A10),IF(ViewMode="Skillsets",IF(Calc!S13="","",6),IF(Calc!G10="","",Calc!G10))) | B14: =IF(ViewMode="Team",IF(A14="","",IF(ISNA(Calc!B10),"",Calc!B10)),IF(ViewMode="Skillsets",IF(A14="","",Calc!S13),IF(A14="","",IF(Calc!H10="","",Calc!H10)))) | C14: =IF(ViewMode="Team",IF(OR(A14="",B14="",NOT(ISNUMBER(B14)),NOT(ISNUMBER(B13))),"",B14-B13),IF(ViewMode="Skillsets",IF(B14="","",IFERROR(INDEX(Employees!C6:C21,MATCH(B14,Employees!B6:B21,0)),"")),IF(A14="","",IF(Calc!I10="","",Calc!I10)))) | D14: =IF(ViewMode="Skillsets",IF(B14="","",IFERROR(INDEX(Calc!N8:N23,MATCH(B14,Calc!L8:L23,0)),"")),IF(ViewMode="Individual",IF(OR(B14="",C14=""),"",C14-B14),"")) | E14: =IF(ViewMode<>"Skillsets","",IF(B14="","",Calc!T13)) | F14: =IF(ViewMode<>"Skillsets","",IF(OR(D14="",E14=""),"",E14-D14))
A15: =IF(ViewMode="Team",IF(Calc!A11="","",Calc!A11),IF(ViewMode="Skillsets",IF(Calc!S14="","",7),IF(Calc!G11="","",Calc!G11))) | B15: =IF(ViewMode="Team",IF(A15="","",IF(ISNA(Calc!B11),"",Calc!B11)),IF(ViewMode="Skillsets",IF(A15="","",Calc!S14),IF(A15="","",IF(Calc!H11="","",Calc!H11)))) | C15: =IF(ViewMode="Team",IF(OR(A15="",B15="",NOT(ISNUMBER(B15)),NOT(ISNUMBER(B14))),"",B15-B14),IF(ViewMode="Skillsets",IF(B15="","",IFERROR(INDEX(Employees!C6:C21,MATCH(B15,Employees!B6:B21,0)),"")),IF(A15="","",IF(Calc!I11="","",Calc!I11)))) | D15: =IF(ViewMode="Skillsets",IF(B15="","",IFERROR(INDEX(Calc!N8:N23,MATCH(B15,Calc!L8:L23,0)),"")),IF(ViewMode="Individual",IF(OR(B15="",C15=""),"",C15-B15),"")) | E15: =IF(ViewMode<>"Skillsets","",IF(B15="","",Calc!T14)) | F15: =IF(ViewMode<>"Skillsets","",IF(OR(D15="",E15=""),"",E15-D15))
A16: =IF(ViewMode="Team",IF(Calc!A12="","",Calc!A12),IF(ViewMode="Skillsets",IF(Calc!S15="","",8),IF(Calc!G12="","",Calc!G12))) | B16: =IF(ViewMode="Team",IF(A16="","",IF(ISNA(Calc!B12),"",Calc!B12)),IF(ViewMode="Skillsets",IF(A16="","",Calc!S15),IF(A16="","",IF(Calc!H12="","",Calc!H12)))) | C16: =IF(ViewMode="Team",IF(OR(A16="",B16="",NOT(ISNUMBER(B16)),NOT(ISNUMBER(B15))),"",B16-B15),IF(ViewMode="Skillsets",IF(B16="","",IFERROR(INDEX(Employees!C6:C21,MATCH(B16,Employees!B6:B21,0)),"")),IF(A16="","",IF(Calc!I12="","",Calc!I12)))) | D16: =IF(ViewMode="Skillsets",IF(B16="","",IFERROR(INDEX(Calc!N8:N23,MATCH(B16,Calc!L8:L23,0)),"")),IF(ViewMode="Individual",IF(OR(B16="",C16=""),"",C16-B16),"")) | E16: =IF(ViewMode<>"Skillsets","",IF(B16="","",Calc!T15)) | F16: =IF(ViewMode<>"Skillsets","",IF(OR(D16="",E16=""),"",E16-D16))
